Workbook

Sheet BD
B2: CÓDIGO | C2: DESCRIÇÃO | D2: UNIDADE | E2: CUSTO ONERADO | F2: CUSTO DESONERADO
B3: 407819 | C3: =UPPER(VLOOKUP(B3,#REF!,2,FALSE)) -> #REF! | D3: =VLOOKUP(B3,#REF!,3,FALSE) -> #REF! | E3: 18.63 | H3: =VLOOKUP(B3,#REF!,1,FALSE) -> #REF! | I3: =VLOOKUP(B3,#REF!,1,FALSE) -> #REF!
B4: 804039 | C4: =UPPER(VLOOKUP(B4,#REF!,2,FALSE)) -> #REF! | D4: =VLOOKUP(B4,#REF!,3,FALSE) -> #REF! | E4: 1154.15 | H4: =VLOOKUP(B4,#REF!,1,FALSE) -> #REF! | I4: =VLOOKUP(B4,#REF!,1,FALSE) -> #REF!
B5: 804191 | C5: =UPPER(VLOOKUP(B5,#REF!,2,FALSE)) -> #REF! | D5: =VLOOKUP(B5,#REF!,3,FALSE) -> #REF! | E5: 2232.12 | H5: =VLOOKUP(B5,#REF!,1,FALSE) -> #REF! | I5: =VLOOKUP(B5,#REF!,1,FALSE) -> #REF!
B6: 804393 | C6: =UPPER(VLOOKUP(B6,#REF!,2,FALSE)) -> #REF! | D6: =VLOOKUP(B6,#REF!,3,FALSE) -> #REF! | E6: 4001.47 | H6: =VLOOKUP(B6,#REF!,1,FALSE) -> #REF! | I6: =VLOOKUP(B6,#REF!,1,FALSE) -> #REF!
B7: 804417 | C7: =UPPER(VLOOKUP(B7,#REF!,2,FALSE)) -> #REF! | D7: =VLOOKUP(B7,#REF!,3,FALSE) -> #REF! | E7: 5578.79 | H7: =VLOOKUP(B7,#REF!,1,FALSE) -> #REF! | I7: =VLOOKUP(B7,#REF!,1,FALSE) -> #REF!
B8: 1106057 | C8: =UPPER(VLOOKUP(B8,#REF!,2,FALSE)) -> #REF! | D8: =VLOOKUP(B8,#REF!,3,FALSE) -> #REF! | E8: 625.61 | H8: =VLOOKUP(B8,#REF!,1,FALSE) -> #REF! | I8: =VLOOKUP(B8,#REF!,1,FALSE) -> #REF!
B9: 1107892 | C9: =UPPER(VLOOKUP(B9,#REF!,2,FALSE)) -> #REF! | D9: =VLOOKUP(B9,#REF!,3,FALSE) -> #REF! | E9: 641.6 | H9: =VLOOKUP(B9,#REF!,1,FALSE) -> #REF! | I9: =VLOOKUP(B9,#REF!,1,FALSE) -> #REF!
B10: 1109671 | C10: =UPPER(VLOOKUP(B10,#REF!,2,FALSE)) -> #REF! | D10: =VLOOKUP(B10,#REF!,3,FALSE) -> #REF! | E10: 626.41 | H10: =VLOOKUP(B10,#REF!,1,FALSE) -> #REF! | I10: =VLOOKUP(B10,#REF!,1,FALSE) -> #REF!
B11: 1505860 | C11: =UPPER(VLOOKUP(B11,#REF!,2,FALSE)) -> #REF! | D11: =VLOOKUP(B11,#REF!,3,FALSE) -> #REF! | E11: 257.64 | H11: =VLOOKUP(B11,#REF!,1,FALSE) -> #REF! | I11: =VLOOKUP(B11,#REF!,1,FALSE) -> #REF!
B12: 1505877 | C12: =UPPER(VLOOKUP(B12,#REF!,2,FALSE)) -> #REF! | D12: =VLOOKUP(B12,#REF!,3,FALSE) -> #REF! | E12: 241.37 | H12: =VLOOKUP(B12,#REF!,1,FALSE) -> #REF! | I12: =VLOOKUP(B12,#REF!,1,FALSE) -> #REF!
B13: 1505879 | C13: =UPPER(VLOOKUP(B13,#REF!,2,FALSE)) -> #REF! | D13: =VLOOKUP(B13,#REF!,3,FALSE) -> #REF! | E13: 405.51 | H13: =VLOOKUP(B13,#REF!,1,FALSE) -> #REF! | I13: =VLOOKUP(B13,#REF!,1,FALSE) -> #REF!
B14: 1600895 | C14: =UPPER(VLOOKUP(B14,#REF!,2,FALSE)) -> #REF! | D14: =VLOOKUP(B14,#REF!,3,FALSE) -> #REF! | E14: 22.46 | H14: =VLOOKUP(B14,#REF!,1,FALSE) -> #REF! | I14: =VLOOKUP(B14,#REF!,1,FALSE) -> #REF!
... B78: 6416078 | C78: =UPPER(VLOOKUP(B78,#REF!,2,FALSE)) -> #REF! | D78: =VLOOKUP(B78,#REF!,3,FALSE) -> #REF! | E78: 213.12 | H78: =VLOOKUP(B78,#REF!,1,FALSE) -> #REF! | I78: =VLOOKUP(B78,#REF!,1,FALSE) -> #REF!
B80: TRANSPORTES
B81: 5914464 | C81: =UPPER(VLOOKUP(B81,#REF!,2,FALSE)) -> #REF! | D81: =VLOOKUP(B81,#REF!,3,FALSE) -> #REF! | E81: 1.19 | H81: =VLOOKUP(B81,#REF!,1,FALSE) -> #REF! | I81: =VLOOKUP(B81,#REF!,1,FALSE) -> #REF!
B82: 5914479 | C82: =UPPER(VLOOKUP(B82,#REF!,2,FALSE)) -> #REF! | D82: =VLOOKUP(B82,#REF!,3,FALSE) -> #REF! | E82: 0.96 | H82: =VLOOKUP(B82,#REF!,1,FALSE) -> #REF! | I82: =VLOOKUP(B82,#REF!,1,FALSE) -> #REF!
B83: 5915014 | C83: =UPPER(VLOOKUP(B83,#REF!,2,FALSE)) -> #REF! | D83: =VLOOKUP(B83,#REF!,3,FALSE) -> #REF! | E83: 1.72 | H83: =VLOOKUP(B83,#REF!,1,FALSE) -> #REF! | I83: =VLOOKUP(B83,#REF!,1,FALSE) -> #REF!
B84: 5915320 | C84: =UPPER(VLOOKUP(B84,#REF!,2,FALSE)) -> #REF! | D84: =VLOOKUP(B84,#REF!,3,FALSE) -> #REF! | E84: 1.03 | H84: =VLOOKUP(B84,#REF!,1,FALSE) -> #REF! | I84: =VLOOKUP(B84,#REF!,1,FALSE) -> #REF!
B85: 5915321 | C85: =UPPER(VLOOKUP(B85,#REF!,2,FALSE)) -> #REF! | D85: =VLOOKUP(B85,#REF!,3,FALSE) -> #REF! | E85: 0.92 | H85: =VLOOKUP(B85,#REF!,1,FALSE) -> #REF! | I85: =VLOOKUP(B85,#REF!,1,FALSE) -> #REF!
B87: SINALIZAÇÃO DE OBRAS TEMPORÁRIAS
B88: 5212556 | C88: =UPPER(VLOOKUP(B88,#REF!,2,FALSE)) -> #REF! | D88: =VLOOKUP(B88,#REF!,3,FALSE) -> #REF! | E88: 1.47 | H88: =VLOOKUP(B88,#REF!,1,FALSE) -> #REF! | I88: =VLOOKUP(B88,#REF!,1,FALSE) -> #REF!
B89: 5212557 | C89: =UPPER(VLOOKUP(B89,#REF!,2,FALSE)) -> #REF! | D89: =VLOOKUP(B89,#REF!,3,FALSE) -> #REF! | E89: 1.55 | H89: =VLOOKUP(B89,#REF!,1,FALSE) -> #REF! | I89: =VLOOKUP(B89,#REF!,1,FALSE) -> #REF!
B90: 5212558 | C90: =UPPER(VLOOKUP(B90,#REF!,2,FALSE)) -> #REF! | D90: =VLOOKUP(B90,#REF!,3,FALSE) -> #REF! | E90: 1.59 | H90: =VLOOKUP(B90,#REF!,1,FALSE) -> #REF! | I90: =VLOOKUP(B90,#REF!,1,FALSE) -> #REF!
B91: 5212560 | C91: =UPPER(VLOOKUP(B91,#REF!,2,FALSE)) -> #REF! | D91: =VLOOKUP(B91,#REF!,3,FALSE) -> #REF! | E91: 1.76 | H91: =VLOOKUP(B91,#REF!,1,FALSE) -> #REF! | I91: =VLOOKUP(B91,#REF!,1,FALSE) -> #REF!
B92: 5213383 | C92: =UPPER(VLOOKUP(B92,#REF!,2,FALSE)) -> #REF! | D92: =VLOOKUP(B92,#REF!,3,FALSE) -> #REF! | E92: 0.82 | H92: =VLOOKUP(B92,#REF!,1,FALSE) -> #REF! | I92: =VLOOKUP(B92,#REF!,1,FALSE) -> #REF!
B93: 5213835 | C93: =UPPER(VLOOKUP(B93,#REF!,2,FALSE)) -> #REF! | D93: =VLOOKUP(B93,#REF!,3,FALSE) -> #REF! | E93: 0.84 | H93: =VLOOKUP(B93,#REF!,1,FALSE) -> #REF! | I93: =VLOOKUP(B93,#REF!,1,FALSE) -> #REF!
B94: 5213838 | C94: =UPPER(VLOOKUP(B94,#REF!,2,FALSE)) -> #REF! | D94: =VLOOKUP(B94,#REF!,3,FALSE) -> #REF! | E94: 6.47 | H94: =VLOOKUP(B94,#REF!,1,FALSE) -> #REF! | I94: =VLOOKUP(B94,#REF!,1,FALSE) -> #REF!
B95: 5213850 | C95: =UPPER(VLOOKUP(B95,#REF!,2,FALSE)) -> #REF! | D95: =VLOOKUP(B95,#REF!,3,FALSE) -> #REF! | E95: 33.58 | H95: =VLOOKUP(B95,#REF!,1,FALSE) -> #REF! | I95: =VLOOKUP(B95,#REF!,1,FALSE) -> #REF!
B97: INDIRETOS
B98: 903810 | C98: =UPPER(VLOOKUP(B98,#REF!,2,FALSE)) -> #REF! | D98: =VLOOKUP(B98,#REF!,3,FALSE) -> #REF! | E98: 207254.72 | H98: =VLOOKUP(B98,#REF!,1,FALSE) -> #REF! | I98: =VLOOKUP(B98,#REF!,1,FALSE) -> #REF!
B100: PREÇOS NOVOS
B101: 4915623A | C101: MACADAME HIDRÁULICO PARA BASE DE REMENDO PROFUNDO - PEDRA COMERCIAL | D101: m³ | E101: 256.58 | H101: =VLOOKUP(B101,#REF!,1,FALSE) -> #REF! | I101: =VLOOKUP(B101,#REF!,1,FALSE) -> #REF!
B102: PN02 | C102: TRANSPORTE COM CAMINHÃO BASCULANTE COM CAÇAMBA ESTANQUE COM CAPACIDADE DE 28 M³ - RODOVIA EM REVESTIMENTO PRIMÁRIO | D102: tkm | E102: 0.93 | H102: =VLOOKUP(B102,#REF!,1,FALSE) -> #REF! | I102: =VLOOKUP(B102,#REF!,1,FALSE) -> #REF!
B103: PN03 | C103: TRANSPORTE COM CAMINHÃO BASCULANTE COM CAÇAMBA ESTANQUE COM CAPACIDADE DE 28 M³ - RODOVIA PAVIMENTADA | D103: tkm | E103: 0.84 | H103: =VLOOKUP(B103,#REF!,1,FALSE) -> #REF! | I103: =VLOOKUP(B103,#REF!,1,FALSE) -> #REF!
B105: DIVERSOS
B106: ADM | C106: ADMINISTRAÇÃO LOCAL | D106: mês | E106: =#REF! -> #REF! | F106: =#REF! -> #REF! | H106: =VLOOKUP(B106,#REF!,1,FALSE) -> #REF! | I106: =VLOOKUP(B106,#REF!,1,FALSE) -> #REF!
B107: CAN | C107: INSTALAÇÃO DO CANTEIRO DE OBRAS E ACAMPAMENTOS | D107: un | E107: =#REF! -> #REF! | F107: =#REF! -> #REF! | H107: =VLOOKUP(B107,#REF!,1,FALSE) -> #REF! | I107: =VLOOKUP(B107,#REF!,1,FALSE) -> #REF!
B108: INSIND | C108: INSTALAÇÃO INDUSTRIAL - USINA DE ASFALTO A QUENTE | D108: un | E108: =#REF! -> #REF! | F108: =#REF! -> #REF! | H108: =VLOOKUP(B108,#REF!,1,FALSE) -> #REF! | I108: =VLOOKUP(B108,#REF!,1,FALSE) -> #REF!
B109: MOB | C109: MOBILIZAÇÃO DE PESSOAL E EQUIPAMENTOS DE GRANDE PORTE | D109: un | E109: =#REF! -> #REF! | F109: =#REF! -> #REF! | H109: =VLOOKUP(B109,#REF!,1,FALSE) -> #REF! | I109: =VLOOKUP(B109,#REF!,1,FALSE) -> #REF!
...

Sheet VMD
B3: VOLUME MÉDIO DIÁRIO
B4: SEGMENTO | C4: ORIGEM | D4: DESTINO | E4: EXT. (KM) | F4: % | G4: VMDf
G5: CRESCENTE | H5: DECRESCENTE
B7: 01 | E7: =D7-C7 -> 0 | F7: =E7/SUM($E$7:$E$8) -> #DIV/0!
B8: 02 | C8: =D7 -> 0 | E8: =D8-C8 -> 0 | F8: =E8/SUM($E$7:$E$8) -> #DIV/0!

Sheet VMDf
C3: VOLUME MÉDIO DIÁRIO FAIXA
C4: INSUMO | D4: ORIGEM | F4: DESTINO | H4: EXTENSÃO (KM) | I4: SENTIDO | J4: SEG1 | N4: SEG2 | S4: VMDf
D5: LOCAL | E5: KM | F5: LOCAL | G5: KM | J5: EXT. (KM) | K5: % | L5: VMDc | M5: VMDd | N5: EXT. (KM) | O5: % | P5: VMDc | Q5: VMDd
C6: =FIT!$C$6 -> CONSERVAÇÃO RODOVIÁRIA
C7: AREIA MÉDIA | D7: AREAL | F7: USINA | H7: =E7-G7 -> 0 | J7: =VMD!$D$7-VMDf!$G$7 -> 0 | K7: =J7/H7 -> #DIV/0! | L7: =VMD!G7 -> 0 | M7: =VMD!H7 -> 0 | N7: =$E$7-VMD!$C$8 -> 0 | O7: =N7/H7 -> #DIV/0! | P7: =VMD!G8 -> 0 | Q7: =VMD!H8 -> 0 | R7: =C7&D7&F7 -> AREIA MÉDIAAREALUSINA | S7: =ROUND((J7*$M$7+N7*$Q$7)/H7,0) -> #DIV/0! | V7: =E8-H8 -> 0
C8: AREIA MÉDIA | D8: AREAL | F8: PISTA | H8: =E8-G8 -> 0 | J8: =VMD!$D$7-VMDf!$G$8 -> 0 | K8: =J8/H8 -> #DIV/0! | N8: =$E$8-VMD!$C$8 -> 0 | O8: =N8/H8 -> #DIV/0! | R8: =C8&D8&F8 -> AREIA MÉDIAAREALPISTA | S8: =ROUND((J8*$M$7+N8*$Q$7)/H8,0) -> #DIV/0!
C9: AREIA MÉDIA LAVADA | D9: AREAL | F9: PISTA | H9: =E9-G9 -> 0 | J9: =VMD!$D$7-VMDf!$G$9 -> 0 | K9: =J9/H9 -> #DIV/0! | N9: =$E$9-VMD!$C$8 -> 0 | O9: =N9/H9 -> #DIV/0! | R9: =C9&D9&F9 -> AREIA MÉDIA LAVADAAREALPISTA | S9: =ROUND((J9*$M$7+N9*$Q$7)/H9,0) -> #DIV/0!
C10: BRITA 0 | D10: PEDREIRA | F10: PISTA | H10: =E10-G10 -> 0 | J10: 0 | K10: =J10/H10 -> #DIV/0! | N10: =VMD!$D$8-G10 -> 0 | O10: =N10/H10 -> #DIV/0! | R10: =C10&D10&F10 -> BRITA 0PEDREIRAPISTA | S10: =ROUND((J10*$M$7+N10*$Q$7)/H10,0) -> #DIV/0!
C11: BRITA 0 | D11: PEDREIRA | F11: USINA | H11: =E11-G11 -> 0 | J11: =VMD!$D$7-VMDf!$G$11 -> 0 | K11: =J11/H11 -> #DIV/0! | N11: =VMD!$E$8 -> 0 | O11: =N11/H11 -> #DIV/0! | R11: =C11&D11&F11 -> BRITA 0PEDREIRAUSINA | S11: =ROUND((J11*$M$7+N11*$Q$7)/H11,0) -> #DIV/0!
C12: BRITA 1 | D12: PEDREIRA | F12: PISTA | H12: =E12-G12 -> 0 | J12: 0 | K12: =J12/H12 -> #DIV/0! | N12: =VMD!$D$8-G12 -> 0 | O12: =N12/H12 -> #DIV/0! | R12: =C12&D12&F12 -> BRITA 1PEDREIRAPISTA | S12: =ROUND((J12*$M$7+N12*$Q$7)/H12,0) -> #DIV/0!
C13: BRITA 1 | D13: PEDREIRA | F13: USINA | H13: =E13-G13 -> 0 | J13: =VMD!$D$7-VMDf!$G$13 -> 0 | K13: =J13/H13 -> #DIV/0! | N13: =VMD!$E$8 -> 0 | O13: =N13/H13 -> #DIV/0! | R13: =C13&D13&F13 -> BRITA 1PEDREIRAUSINA | S13: =ROUND((J13*$M$7+N13*$Q$7)/H13,0) -> #DIV/0!
C14: BRITA 2 | D14: PEDREIRA | F14: PISTA | H14: =E14-G14 -> 0 | J14: 0 | K14: =J14/H14 -> #DIV/0! | N14: =VMD!$D$8-G14 -> 0 | O14: =N14/H14 -> #DIV/0! | R14: =C14&D14&F14 -> BRITA 2PEDREIRAPISTA | S14: =ROUND((J14*$M$7+N14*$Q$7)/H14,0) -> #DIV/0!
C15: BRITA 4 | D15: PEDREIRA | F15: PISTA | H15: =E15-G15 -> 0 | J15: 0 | K15: =J15/H15 -> #DIV/0! | N15: =VMD!$D$8-G15 -> 0 | O15: =N15/H15 -> #DIV/0! | R15: =C15&D15&F15 -> BRITA 4PEDREIRAPISTA | S15: =ROUND((J15*$M$7+N15*$Q$7)/H15,0) -> #DIV/0!
C16: PEDRA DE MÃO | D16: PEDREIRA | F16: PISTA | H16: =E16-G16 -> 0 | J16: 0 | K16: =J16/H16 -> #DIV/0! | N16: =VMD!$D$8-G16 -> 0 | O16: =N16/H16 -> #DIV/0! | R16: =C16&D16&F16 -> PEDRA DE MÃOPEDREIRAPISTA | S16: =ROUND((J16*$M$7+N16*$Q$7)/H16,0) -> #DIV/0!
C17: PEDRISCO | D17: PEDREIRA | F17: USINA | H17: =E17-G17 -> 0 | J17: =VMD!$D$7-VMDf!$G$17 -> 0 | K17: =J17/H17 -> #DIV/0! | N17: =VMD!$E$8 -> 0 | O17: =N17/H17 -> #DIV/0! | R17: =C17&D17&F17 -> PEDRISCOPEDREIRAUSINA | S17: =ROUND((J17*$M$7+N17*$Q$7)/H17,0) -> #DIV/0!
C18: PÓ DE PEDRA | D18: PEDREIRA | F18: PISTA | H18: =E18-G18 -> 0 | J18: 0 | K18: =J18/H18 -> #DIV/0! | N18: =VMD!$D$8-G18 -> 0 | O18: =N18/H18 -> #DIV/0! | R18: =C18&D18&F18 -> PÓ DE PEDRAPEDREIRAPISTA | S18: =ROUND((J18*$M$7+N18*$Q$7)/H18,0) -> #DIV/0!
C19: PÓ DE PEDRA | D19: PEDREIRA | F19: USINA | H19: =E19-G19 -> 0 | J19: =VMD!$D$7-VMDf!$G$19 -> 0 | K19: =J19/H19 -> #DIV/0! | N19: =VMD!$E$8 -> 0 | O19: =N19/H19 -> #DIV/0! | R19: =C19&D19&F19 -> PÓ DE PEDRAPEDREIRAUSINA | S19: =ROUND((J19*$M$7+N19*$Q$7)/H19,0) -> #DIV/0!
C20: MISTURA BETUMINOSA | D20: USINA | F20: PISTA | H20: =G20-E20 -> 0 | J20: =VMD!$D$7-VMDf!$E$20 -> 0 | K20: =J20/H20 -> #DIV/0! | N20: =$G$20-VMD!$D$7 -> 0 | O20: =N20/H20 -> #DIV/0! | R20: =C20&D20&F20 -> MISTURA BETUMINOSAUSINAPISTA | S20: =ROUND((J20*$L$7+N20*$P$7)/H20,0) -> #DIV/0!

Sheet FIT
C3: FATOR DE INTERFERÊNCIA DE TRÁFEGO - FIT
C4: CÓDIGO | D4: SERVIÇO | E4: INSUMO | F4: ORIGEM | G4: DESTINO | H4: OCULTAR | I4: KM-i | J4: KM-f | K4: SENTIDO | L4: DMTp (km) | M4: INTERF. | N4: DMTr (km) | O4: DMTu (km) | P4: VMDf | Q4: Atraso A1 (s) | R4: Atraso A2 (s) | S4: FIT
C6: CONSERVAÇÃO RODOVIÁRIA
H7: =E7&F7&G7 | I7: 44.3 | J7: 23.011882 | M7: =IF(L7>=100,"NÃO","SIM") -> SIM | N7: =VLOOKUP(H7,#REF!,8,FALSE) -> #REF! | R7: =60*O7 -> 0 | S7: =IF(M7="NÃO",1,1+(Q7+R7)/(L7*60)) -> #DIV/0!
H8: =E8&F8&G8 | I8: 85 | J8: 42.5 | M8: =IF(L8>=100,"NÃO","SIM") -> SIM | N8: =VLOOKUP(H8,#REF!,8,FALSE) -> #REF! | R8: =60*O8 -> 0 | S8: =IF(M8="NÃO",1,1+(Q8+R8)/(L8*60)) -> #DIV/0!
H9: =E9&F9&G9 | I9: 85 | J9: 42.5 | M9: =IF(L9>=100,"NÃO","SIM") -> SIM | N9: =VLOOKUP(H9,#REF!,8,FALSE) -> #REF! | R9: =60*O9 -> 0 | S9: =IF(M9="NÃO",1,1+(Q9+R9)/(L9*60)) -> #DIV/0!
H10: =E10&F10&G10 | I10: 85 | J10: 42.5 | M10: =IF(L10>=100,"NÃO","SIM") -> SIM | N10: =VLOOKUP(H10,#REF!,8,FALSE) -> #REF! | R10: =60*O10 -> 0 | S10: =IF(M10="NÃO",1,1+(Q10+R10)/(L10*60)) -> #DIV/0!
H11: =E11&F11&G11 | I11: 44.3 | J11: 23.011882 | M11: =IF(L11>=100,"NÃO","SIM") -> SIM | N11: =VLOOKUP(H11,#REF!,8,FALSE) -> #REF! | R11: =60*O11 -> 0 | S11: =IF(M11="NÃO",1,1+(Q11+R11)/(L11*60)) -> #DIV/0!
H12: =E12&F12&G12 | I12: 85 | J12: 42.5 | M12: =IF(L12>=100,"NÃO","SIM") -> SIM | N12: =VLOOKUP(H12,#REF!,8,FALSE) -> #REF! | R12: =60*O12 -> 0 | S12: =IF(M12="NÃO",1,1+(Q12+R12)/(L12*60)) -> #DIV/0!
H13: =E13&F13&G13 | I13: 85 | J13: 42.5 | M13: =IF(L13>=100,"NÃO","SIM") -> SIM | N13: =VLOOKUP(H13,#REF!,8,FALSE) -> #REF! | R13: =60*O13 -> 0 | S13: =IF(M13="NÃO",1,1+(Q13+R13)/(L13*60)) -> #DIV/0!
H14: =E14&F14&G14 | I14: 85 | J14: 42.5 | M14: =IF(L14>=100,"NÃO","SIM") -> SIM | N14: =VLOOKUP(H14,#REF!,8,FALSE) -> #REF! | R14: =60*O14 -> 0 | S14: =IF(M14="NÃO",1,1+(Q14+R14)/(L14*60)) -> #DIV/0!
H15: =E15&F15&G15 | I15: 44.3 | J15: 23.011882 | M15: =IF(L15>=100,"NÃO","SIM") -> SIM | N15: =VLOOKUP(H15,#REF!,8,FALSE) -> #REF! | R15: =60*O15 -> 0 | S15: =IF(M15="NÃO",1,1+(Q15+R15)/(L15*60)) -> #DIV/0!
H16: =E16&F16&G16 | I16: 85 | J16: 42.5 | M16: =IF(L16>=100,"NÃO","SIM") -> SIM | N16: =VLOOKUP(H16,#REF!,8,FALSE) -> #REF! | R16: =60*O16 -> 0 | S16: =IF(M16="NÃO",1,1+(Q16+R16)/(L16*60)) -> #DIV/0!
H17: =E17&F17&G17 | I17: 85 | J17: 42.5 | M17: =IF(L17>=100,"NÃO","SIM") -> SIM | N17: =VLOOKUP(H17,#REF!,8,FALSE) -> #REF! | R17: =60*O17 -> 0 | S17: =IF(M17="NÃO",1,1+(Q17+R17)/(L17*60)) -> #DIV/0!
H18: =E18&F18&G18 | I18: 44.3 | J18: 23.011882 | M18: =IF(L18>=100,"NÃO","SIM") -> SIM | N18: =VLOOKUP(H18,#REF!,8,FALSE) -> #REF! | R18: =60*O18 -> 0 | S18: =IF(M18="NÃO",1,1+(Q18+R18)/(L18*60)) -> #DIV/0!
... H58: =E58&F58&G58 | I58: 85 | J58: 38 | M58: =IF(L58>=100,"NÃO","SIM") -> SIM | N58: =VLOOKUP(H58,#REF!,8,FALSE) -> #REF! | R58: =60*O58 -> 0 | S58: =IF(M58="NÃO",1,1+(Q58+R58)/(L58*60)) -> #DIV/0!

Sheet TRANSPORTES
B3: QUADRO DE TRANSPORTES
B6: CÓDIGO | C6: DISCRIMINAÇÃO | D6: MATERIAL | E6: QUANT. ANUAL | F6: UNID. | G6: F. UTILIZAÇÃO | I6: PESO | J6: REFERÊNCIA | L6: OCULTAR | M6: DMT | N6: FIT | O6: MOMENTO
E7: TRABALHO | G7: FATOR | H7: UND. | I7: (t) | J7: Origem | K7: Destino | M7: (km) | O7: TRANSP.(tkm)
H8: ="t/"&F8 -> t/ | I8: =G8*E8 -> 0 | O8: =TRUNC(I8*M8*N8,3) -> 0
H9: ="t/"&F9 -> t/ | I9: =G9*E9 -> 0 | O9: =TRUNC(I9*M9*N9,3) -> 0
H10: ="t/"&F10 -> t/ | I10: =G10*E10 -> 0 | O10: =TRUNC(I10*M10*N10,3) -> 0
H11: ="t/"&F11 -> t/ | I11: =G11*E11 -> 0 | O11: =TRUNC(I11*M11*N11,3) -> 0
H12: ="t/"&F12 -> t/ | I12: =G12*E12 -> 0 | O12: =TRUNC(I12*M12*N12,3) -> 0
H13: ="t/"&F13 -> t/ | I13: =G13*E13 -> 0 | O13: =TRUNC(I13*M13*N13,3) -> 0
H14: ="t/"&F14 -> t/ | I14: =G14*E14 -> 0 | O14: =TRUNC(I14*M14*N14,3) -> 0
H15: ="t/"&F15 -> t/ | I15: =G15*E15 -> 0 | O15: =TRUNC(I15*M15*N15,3) -> 0
H16: ="t/"&F16 -> t/ | I16: =G16*E16 -> 0 | O16: =TRUNC(I16*M16*N16,3) -> 0
H17: ="t/"&F17 -> t/ | I17: =G17*E17 -> 0 | O17: =TRUNC(I17*M17*N17,3) -> 0
H18: ="t/"&F18 -> t/ | I18: =G18*E18 -> 0 | O18: =TRUNC(I18*M18*N18,3) -> 0
H19: ="t/"&F19 -> t/ | I19: =G19*E19 -> 0 | O19: =TRUNC(I19*M19*N19,3) -> 0
... H48: ="t/"&F48 -> t/ | I48: =G48*E48 -> 0 | O48: =TRUNC(I48*M48*N48,3) -> 0
H49: t/t | I49: =G49*E49 -> 0 | O49: =TRUNC(I49*M49*N49,3) -> 0
H50: t/t | I50: =G50*E50 -> 0 | O50: =TRUNC(I50*M50*N50,3) -> 0
H51: t/t | I51: =G51*E51 -> 0 | O51: =TRUNC(I51*M51*N51,3) -> 0
H52: t/t | I52: =G52*E52 -> 0 | O52: =TRUNC(I52*M52*N52,3) -> 0
H53: t/t | I53: =G53*E53 -> 0 | O53: =TRUNC(I53*M53*N53,3) -> 0
H54: t/t | I54: =G54*E54 -> 0 | O54: =TRUNC(I54*M54*N54,3) -> 0
H55: t/t | I55: =G55*E55 -> 0 | O55: =TRUNC(I55*M55*N55,3) -> 0
H56: t/t | I56: =G56*E56 -> 0 | O56: =TRUNC(I56*M56*N56,3) -> 0
H57: t/t | I57: =G57*E57 -> 0 | O57: =TRUNC(I57*M57*N57,3) -> 0
H58: t/t | I58: =G58*E58 -> 0 | O58: =TRUNC(I58*M58*N58,3) -> 0
H59: ="t/"&F59 -> t/ | I59: =G59*E59 -> 0 | O59: =TRUNC(I59*M59*N59,3) -> 0
H60: ="t/"&F60 -> t/ | I60: =G60*E60 -> 0 | O60: =TRUNC(I60*M60*N60,3) -> 0
H61: ="t/"&F61 -> t/ | I61: =G61*E61 -> 0 | O61: =TRUNC(I61*M61*N61,3) -> 0
H62: ="t/"&F62 -> t/ | I62: =G62*E62 -> 0 | O62: =TRUNC(I62*M62*N62,3) -> 0
H63: ="t/"&F63 -> t/ | I63: =G63*E63 -> 0 | O63: =TRUNC(I63*M63*N63,3) -> 0
H64: ="t/"&F64 -> t/ | I64: =G64*E64 -> 0 | O64: =TRUNC(I64*M64*N64,3) -> 0
H65: ="t/"&F65 -> t/ | I65: =G65*E65 -> 0 | O65: =TRUNC(I65*M65*N65,3) -> 0
H66: ="t/"&F66 -> t/ | I66: =G66*E66 -> 0 | O66: =TRUNC(I66*M66*N66,3) -> 0
B68: TOTAL: | O68: =SUM(O7:O67) -> 0
